[2019-12-17 14:39:08] [INFO] [MainThread] [handlers.py:63] Request Infomations:
+-----Headers-----+
| Content-Type    | application/x-www-form-urlencoded 
| Authorization   | eyJ0eXAiOiJKV1QiLCJhbGciOiJIUzI1NiJ9.eyJpZCI6MSwibmlja19uYW1lIjpudWxsLCJleHAiOjE1NzYyMjI3NTR9.KdwdPYH43DI8Qt2bY08dEz5fUhB-lnD5S3NCS2iF4fo 
| User-Agent      | PostmanRuntime/7.20.1 
| Accept          | */*             
| Cache-Control   | no-cache        
| Postman-Token   | 5d6bba65-2f0d-48b9-ac45-c39cf5ea0337 
| Host            | 127.0.0.1:8084  
| Accept-Encoding | gzip, deflate   
| Content-Length  | 141             
| Connection      | keep-alive      
+----Arguments----+
| 'test_name'     | '嘻嘻嘻'           
| 'assertion'     | '1231'          
| 'desc'          | 11111           
| 'interfaces'    | [8, 9]          
| 'db_check'      | [{'db': 8, 'assertSql': 1111}] 

[2019-12-17 14:39:08] [INFO] [MainThread] [handlers.py:44] Response Infomations:
+-----Headers-----+
| Content-Type    | application/json 

Body:
| {
|     "code": 10020,
|     "msg": "这个用例已经创建！",
|     "data": null
| }
[2019-12-17 14:39:11] [INFO] [MainThread] [handlers.py:63] Request Infomations:
+-----Headers-----+
| Content-Type    | application/x-www-form-urlencoded 
| Authorization   | eyJ0eXAiOiJKV1QiLCJhbGciOiJIUzI1NiJ9.eyJpZCI6MSwibmlja19uYW1lIjpudWxsLCJleHAiOjE1NzYyMjI3NTR9.KdwdPYH43DI8Qt2bY08dEz5fUhB-lnD5S3NCS2iF4fo 
| User-Agent      | PostmanRuntime/7.20.1 
| Accept          | */*             
| Cache-Control   | no-cache        
| Postman-Token   | 02cf1efe-7732-44ca-b711-efc65275736b 
| Host            | 127.0.0.1:8084  
| Accept-Encoding | gzip, deflate   
| Content-Length  | 142             
| Connection      | keep-alive      
+----Arguments----+
| 'test_name'     | '嘻2嘻嘻'          
| 'assertion'     | '1231'          
| 'desc'          | 11111           
| 'interfaces'    | [8, 9]          
| 'db_check'      | [{'db': 8, 'assertSql': 1111}] 

[2019-12-17 14:39:11] [ERROR] [MainThread] [handlers.py:105] Uncaught exception POST /cases/ (127.0.0.1)
HTTPServerRequest(protocol='http', host='127.0.0.1:8084', method='POST', uri='/cases/', version='HTTP/1.1', remote_ip='127.0.0.1')
Traceback (most recent call last):
  File "D:\Users\Null\AppData\Local\Continuum\miniconda3\lib\site-packages\peewee_async.py", line 170, in get
    return list(result)[0]
IndexError: list index out of range

During handling of the above exception, another exception occurred:

Traceback (most recent call last):
  File "F:\MagicTestPlatform\apps\interface_test\handlers.py", line 292, in post
    TestCases, test_name=form.test_name.data
  File "D:\Users\Null\AppData\Local\Continuum\miniconda3\lib\site-packages\peewee_async.py", line 172, in get
    raise model.DoesNotExist
apps.interface_test.models.TestCasesDoesNotExist

During handling of the above exception, another exception occurred:

Traceback (most recent call last):
  File "D:\Users\Null\AppData\Local\Continuum\miniconda3\lib\site-packages\peewee_async.py", line 1540, in _run_sql
    yield from cursor.execute(operation, *args, **kwargs)
  File "D:\Users\Null\AppData\Local\Continuum\miniconda3\lib\site-packages\aiomysql\cursors.py", line 239, in execute
    await self._query(query)
  File "D:\Users\Null\AppData\Local\Continuum\miniconda3\lib\site-packages\aiomysql\cursors.py", line 457, in _query
    await conn.query(q)
  File "D:\Users\Null\AppData\Local\Continuum\miniconda3\lib\site-packages\aiomysql\connection.py", line 428, in query
    await self._read_query_result(unbuffered=unbuffered)
  File "D:\Users\Null\AppData\Local\Continuum\miniconda3\lib\site-packages\aiomysql\connection.py", line 622, in _read_query_result
    await result.read()
  File "D:\Users\Null\AppData\Local\Continuum\miniconda3\lib\site-packages\aiomysql\connection.py", line 1105, in read
    first_packet = await self.connection._read_packet()
  File "D:\Users\Null\AppData\Local\Continuum\miniconda3\lib\site-packages\aiomysql\connection.py", line 593, in _read_packet
    packet.check_error()
  File "D:\Users\Null\AppData\Local\Continuum\miniconda3\lib\site-packages\pymysql\protocol.py", line 220, in check_error
    err.raise_mysql_exception(self._data)
  File "D:\Users\Null\AppData\Local\Continuum\miniconda3\lib\site-packages\pymysql\err.py", line 109, in raise_mysql_exception
    raise errorclass(errno, errval)
pymysql.err.IntegrityError: (1452, 'Cannot add or update a child row: a foreign key constraint fails (`magic`.`checkdbcontent`, CONSTRAINT `checkdbcontent_ibfk_1` FOREIGN KEY (`db_id`) REFERENCES `dbsetting` (`id`))')

During handling of the above exception, another exception occurred:

Traceback (most recent call last):
  File "D:\Users\Null\AppData\Local\Continuum\miniconda3\lib\site-packages\tornado\web.py", line 1699, in _execute
    result = await result
  File "F:\MagicTestPlatform\common\core.py", line 69, in wrapper
    await method(self, *args, **kwargs)
  File "F:\MagicTestPlatform\apps\interface_test\handlers.py", line 326, in post
    case=case.id
  File "D:\Users\Null\AppData\Local\Continuum\miniconda3\lib\site-packages\peewee_async.py", line 181, in create
    pk = yield from self.execute(query)
  File "D:\Users\Null\AppData\Local\Continuum\miniconda3\lib\site-packages\peewee_async.py", line 269, in execute
    return (yield from execute(query))
  File "D:\Users\Null\AppData\Local\Continuum\miniconda3\lib\site-packages\peewee_async.py", line 433, in execute
    return (yield from coroutine(query))
  File "D:\Users\Null\AppData\Local\Continuum\miniconda3\lib\site-packages\peewee_async.py", line 597, in insert
    cursor = yield from _execute_query_async(query)
  File "D:\Users\Null\AppData\Local\Continuum\miniconda3\lib\site-packages\peewee_async.py", line 1558, in _execute_query_async
    return (yield from _run_sql(query.database, *query.sql()))
  File "D:\Users\Null\AppData\Local\Continuum\miniconda3\lib\site-packages\peewee_async.py", line 1545, in _run_sql
    return cursor
  File "D:\Users\Null\AppData\Local\Continuum\miniconda3\lib\site-packages\peewee.py", line 3656, in __exit__
    reraise(new_type, new_type(*exc_args), traceback)
  File "D:\Users\Null\AppData\Local\Continuum\miniconda3\lib\site-packages\peewee.py", line 135, in reraise
    raise value.with_traceback(tb)
  File "D:\Users\Null\AppData\Local\Continuum\miniconda3\lib\site-packages\peewee_async.py", line 1540, in _run_sql
    yield from cursor.execute(operation, *args, **kwargs)
  File "D:\Users\Null\AppData\Local\Continuum\miniconda3\lib\site-packages\aiomysql\cursors.py", line 239, in execute
    await self._query(query)
  File "D:\Users\Null\AppData\Local\Continuum\miniconda3\lib\site-packages\aiomysql\cursors.py", line 457, in _query
    await conn.query(q)
  File "D:\Users\Null\AppData\Local\Continuum\miniconda3\lib\site-packages\aiomysql\connection.py", line 428, in query
    await self._read_query_result(unbuffered=unbuffered)
  File "D:\Users\Null\AppData\Local\Continuum\miniconda3\lib\site-packages\aiomysql\connection.py", line 622, in _read_query_result
    await result.read()
  File "D:\Users\Null\AppData\Local\Continuum\miniconda3\lib\site-packages\aiomysql\connection.py", line 1105, in read
    first_packet = await self.connection._read_packet()
  File "D:\Users\Null\AppData\Local\Continuum\miniconda3\lib\site-packages\aiomysql\connection.py", line 593, in _read_packet
    packet.check_error()
  File "D:\Users\Null\AppData\Local\Continuum\miniconda3\lib\site-packages\pymysql\protocol.py", line 220, in check_error
    err.raise_mysql_exception(self._data)
  File "D:\Users\Null\AppData\Local\Continuum\miniconda3\lib\site-packages\pymysql\err.py", line 109, in raise_mysql_exception
    raise errorclass(errno, errval)
peewee.IntegrityError: (1452, 'Cannot add or update a child row: a foreign key constraint fails (`magic`.`checkdbcontent`, CONSTRAINT `checkdbcontent_ibfk_1` FOREIGN KEY (`db_id`) REFERENCES `dbsetting` (`id`))')
[2019-12-17 14:39:11] [INFO] [MainThread] [handlers.py:44] Response Infomations:
+-----Headers-----+
| Content-Type    | text/plain      

Body:
| Traceback (most recent call last):
| 
