[2019-12-20 17:06:18] [INFO] [MainThread] [handlers.py:63] Request Infomations:
+-----Headers-----+
| Host            | 127.0.0.1:8084  
| Connection      | keep-alive      
| Access-Control-Request-Method | POST            
| Origin          | http://localhost:8080 
| User-Agent      | Mozilla/5.0 (Windows NT 10.0; WOW64) AppleWebKit/537.36 (KHTML, like Gecko) Chrome/78.0.3904.87 Safari/537.36 
| Access-Control-Request-Headers | content-type    
| Accept          | */*             
| Sec-Fetch-Site  | cross-site      
| Sec-Fetch-Mode  | cors            
| Referer         | http://localhost:8080/login 
| Accept-Encoding | gzip, deflate, br 
| Accept-Language | zh-CN,zh;q=0.9  

[2019-12-20 17:06:18] [INFO] [MainThread] [handlers.py:44] Response Infomations:
+-----Headers-----+
| Content-Type    | application/json 

Body:
| LoginHandler object has list index out of range
[2019-12-20 17:06:18] [INFO] [MainThread] [handlers.py:63] Request Infomations:
+-----Headers-----+
| Host            | 127.0.0.1:8084  
| Connection      | keep-alive      
| Content-Length  | 48              
| Accept          | application/json, text/plain, */* 
| Origin          | http://localhost:8080 
| User-Agent      | Mozilla/5.0 (Windows NT 10.0; WOW64) AppleWebKit/537.36 (KHTML, like Gecko) Chrome/78.0.3904.87 Safari/537.36 
| Content-Type    | application/json;charset=UTF-8 
| Sec-Fetch-Site  | cross-site      
| Sec-Fetch-Mode  | cors            
| Referer         | http://localhost:8080/login 
| Accept-Encoding | gzip, deflate, br 
| Accept-Language | zh-CN,zh;q=0.9  
+----Arguments----+
| 'account'       | '123456@163.com' 
| 'password'      | '123456'        

[2019-12-20 17:06:19] [ERROR] [MainThread] [handlers.py:105] Uncaught exception POST /login/ (127.0.0.1)
HTTPServerRequest(protocol='http', host='127.0.0.1:8084', method='POST', uri='/login/', version='HTTP/1.1', remote_ip='127.0.0.1')
Traceback (most recent call last):
  File "D:\Users\Null\AppData\Local\Continuum\miniconda3\lib\site-packages\aiomysql\connection.py", line 503, in _connect
    await self._request_authentication()
  File "D:\Users\Null\AppData\Local\Continuum\miniconda3\lib\site-packages\aiomysql\connection.py", line 796, in _request_authentication
    await self._process_auth(plugin_name, auth_packet)
  File "D:\Users\Null\AppData\Local\Continuum\miniconda3\lib\site-packages\aiomysql\connection.py", line 848, in _process_auth
    pkt = await self._read_packet()
  File "D:\Users\Null\AppData\Local\Continuum\miniconda3\lib\site-packages\aiomysql\connection.py", line 593, in _read_packet
    packet.check_error()
  File "D:\Users\Null\AppData\Local\Continuum\miniconda3\lib\site-packages\pymysql\protocol.py", line 220, in check_error
    err.raise_mysql_exception(self._data)
  File "D:\Users\Null\AppData\Local\Continuum\miniconda3\lib\site-packages\pymysql\err.py", line 109, in raise_mysql_exception
    raise errorclass(errno, errval)
pymysql.err.OperationalError: (1045, "Access denied for user 'root'@'localhost' (using password: NO)")

The above exception was the direct cause of the following exception:

Traceback (most recent call last):
  File "D:\Users\Null\AppData\Local\Continuum\miniconda3\lib\site-packages\tornado\web.py", line 1699, in _execute
    result = await result
  File "F:\MagicTestPlatform\apps\users\handlers.py", line 87, in post
    user = await self.application.objects.get(User, account=account)
  File "D:\Users\Null\AppData\Local\Continuum\miniconda3\lib\site-packages\peewee_async.py", line 153, in get
    yield from self.connect()
  File "D:\Users\Null\AppData\Local\Continuum\miniconda3\lib\site-packages\peewee_async.py", line 303, in connect
    yield from self.database.connect_async(loop=self.loop)
  File "D:\Users\Null\AppData\Local\Continuum\miniconda3\lib\site-packages\peewee_async.py", line 907, in connect_async
    yield from conn.connect()
  File "D:\Users\Null\AppData\Local\Continuum\miniconda3\lib\site-packages\peewee_async.py", line 1260, in connect
    **self.connect_kwargs)
  File "D:\Users\Null\AppData\Local\Continuum\miniconda3\lib\site-packages\aiomysql\pool.py", line 29, in _create_pool
    await pool._fill_free_pool(False)
  File "D:\Users\Null\AppData\Local\Continuum\miniconda3\lib\site-packages\aiomysql\pool.py", line 168, in _fill_free_pool
    **self._conn_kwargs)
  File "D:\Users\Null\AppData\Local\Continuum\miniconda3\lib\site-packages\aiomysql\connection.py", line 75, in _connect
    await conn._connect()
  File "D:\Users\Null\AppData\Local\Continuum\miniconda3\lib\site-packages\aiomysql\connection.py", line 523, in _connect
    self._host) from e
pymysql.err.OperationalError: (2003, "Can't connect to MySQL server on '127.0.0.1'")
[2019-12-20 17:06:19] [INFO] [MainThread] [handlers.py:44] Response Infomations:
+-----Headers-----+
| Content-Type    | text/plain      

Body:
| Traceback (most recent call last):
| 
[2019-12-20 17:06:19] [INFO] [MainThread] [handlers.py:63] Request Infomations:
+-----Headers-----+
| Host            | 127.0.0.1:8084  
| Connection      | keep-alive      
| Content-Length  | 48              
| Accept          | application/json, text/plain, */* 
| Origin          | http://localhost:8080 
| User-Agent      | Mozilla/5.0 (Windows NT 10.0; WOW64) AppleWebKit/537.36 (KHTML, like Gecko) Chrome/78.0.3904.87 Safari/537.36 
| Content-Type    | application/json;charset=UTF-8 
| Sec-Fetch-Site  | cross-site      
| Sec-Fetch-Mode  | cors            
| Referer         | http://localhost:8080/login 
| Accept-Encoding | gzip, deflate, br 
| Accept-Language | zh-CN,zh;q=0.9  
+----Arguments----+
| 'account'       | '123456@163.com' 
| 'password'      | '123456'        

[2019-12-20 17:06:19] [ERROR] [MainThread] [handlers.py:105] Uncaught exception POST /login/ (127.0.0.1)
HTTPServerRequest(protocol='http', host='127.0.0.1:8084', method='POST', uri='/login/', version='HTTP/1.1', remote_ip='127.0.0.1')
Traceback (most recent call last):
  File "D:\Users\Null\AppData\Local\Continuum\miniconda3\lib\site-packages\aiomysql\connection.py", line 503, in _connect
    await self._request_authentication()
  File "D:\Users\Null\AppData\Local\Continuum\miniconda3\lib\site-packages\aiomysql\connection.py", line 796, in _request_authentication
    await self._process_auth(plugin_name, auth_packet)
  File "D:\Users\Null\AppData\Local\Continuum\miniconda3\lib\site-packages\aiomysql\connection.py", line 848, in _process_auth
    pkt = await self._read_packet()
  File "D:\Users\Null\AppData\Local\Continuum\miniconda3\lib\site-packages\aiomysql\connection.py", line 593, in _read_packet
    packet.check_error()
  File "D:\Users\Null\AppData\Local\Continuum\miniconda3\lib\site-packages\pymysql\protocol.py", line 220, in check_error
    err.raise_mysql_exception(self._data)
  File "D:\Users\Null\AppData\Local\Continuum\miniconda3\lib\site-packages\pymysql\err.py", line 109, in raise_mysql_exception
    raise errorclass(errno, errval)
pymysql.err.OperationalError: (1045, "Access denied for user 'root'@'localhost' (using password: NO)")

The above exception was the direct cause of the following exception:

Traceback (most recent call last):
  File "D:\Users\Null\AppData\Local\Continuum\miniconda3\lib\site-packages\tornado\web.py", line 1699, in _execute
    result = await result
  File "F:\MagicTestPlatform\apps\users\handlers.py", line 87, in post
    user = await self.application.objects.get(User, account=account)
  File "D:\Users\Null\AppData\Local\Continuum\miniconda3\lib\site-packages\peewee_async.py", line 153, in get
    yield from self.connect()
  File "D:\Users\Null\AppData\Local\Continuum\miniconda3\lib\site-packages\peewee_async.py", line 303, in connect
    yield from self.database.connect_async(loop=self.loop)
  File "D:\Users\Null\AppData\Local\Continuum\miniconda3\lib\site-packages\peewee_async.py", line 907, in connect_async
    yield from conn.connect()
  File "D:\Users\Null\AppData\Local\Continuum\miniconda3\lib\site-packages\peewee_async.py", line 1260, in connect
    **self.connect_kwargs)
  File "D:\Users\Null\AppData\Local\Continuum\miniconda3\lib\site-packages\aiomysql\pool.py", line 29, in _create_pool
    await pool._fill_free_pool(False)
  File "D:\Users\Null\AppData\Local\Continuum\miniconda3\lib\site-packages\aiomysql\pool.py", line 168, in _fill_free_pool
    **self._conn_kwargs)
  File "D:\Users\Null\AppData\Local\Continuum\miniconda3\lib\site-packages\aiomysql\connection.py", line 75, in _connect
    await conn._connect()
  File "D:\Users\Null\AppData\Local\Continuum\miniconda3\lib\site-packages\aiomysql\connection.py", line 523, in _connect
    self._host) from e
pymysql.err.OperationalError: (2003, "Can't connect to MySQL server on '127.0.0.1'")
[2019-12-20 17:06:19] [INFO] [MainThread] [handlers.py:44] Response Infomations:
+-----Headers-----+
| Content-Type    | text/plain      

Body:
| Traceback (most recent call last):
| 
[2019-12-20 17:06:19] [INFO] [MainThread] [handlers.py:63] Request Infomations:
+-----Headers-----+
| Host            | 127.0.0.1:8084  
| Connection      | keep-alive      
| Content-Length  | 48              
| Accept          | application/json, text/plain, */* 
| Origin          | http://localhost:8080 
| User-Agent      | Mozilla/5.0 (Windows NT 10.0; WOW64) AppleWebKit/537.36 (KHTML, like Gecko) Chrome/78.0.3904.87 Safari/537.36 
| Content-Type    | application/json;charset=UTF-8 
| Sec-Fetch-Site  | cross-site      
| Sec-Fetch-Mode  | cors            
| Referer         | http://localhost:8080/login 
| Accept-Encoding | gzip, deflate, br 
| Accept-Language | zh-CN,zh;q=0.9  
+----Arguments----+
| 'account'       | '123456@163.com' 
| 'password'      | '123456'        

[2019-12-20 17:06:19] [ERROR] [MainThread] [handlers.py:105] Uncaught exception POST /login/ (127.0.0.1)
HTTPServerRequest(protocol='http', host='127.0.0.1:8084', method='POST', uri='/login/', version='HTTP/1.1', remote_ip='127.0.0.1')
Traceback (most recent call last):
  File "D:\Users\Null\AppData\Local\Continuum\miniconda3\lib\site-packages\aiomysql\connection.py", line 503, in _connect
    await self._request_authentication()
  File "D:\Users\Null\AppData\Local\Continuum\miniconda3\lib\site-packages\aiomysql\connection.py", line 796, in _request_authentication
    await self._process_auth(plugin_name, auth_packet)
  File "D:\Users\Null\AppData\Local\Continuum\miniconda3\lib\site-packages\aiomysql\connection.py", line 848, in _process_auth
    pkt = await self._read_packet()
  File "D:\Users\Null\AppData\Local\Continuum\miniconda3\lib\site-packages\aiomysql\connection.py", line 593, in _read_packet
    packet.check_error()
  File "D:\Users\Null\AppData\Local\Continuum\miniconda3\lib\site-packages\pymysql\protocol.py", line 220, in check_error
    err.raise_mysql_exception(self._data)
  File "D:\Users\Null\AppData\Local\Continuum\miniconda3\lib\site-packages\pymysql\err.py", line 109, in raise_mysql_exception
    raise errorclass(errno, errval)
pymysql.err.OperationalError: (1045, "Access denied for user 'root'@'localhost' (using password: NO)")

The above exception was the direct cause of the following exception:

Traceback (most recent call last):
  File "D:\Users\Null\AppData\Local\Continuum\miniconda3\lib\site-packages\tornado\web.py", line 1699, in _execute
    result = await result
  File "F:\MagicTestPlatform\apps\users\handlers.py", line 87, in post
    user = await self.application.objects.get(User, account=account)
  File "D:\Users\Null\AppData\Local\Continuum\miniconda3\lib\site-packages\peewee_async.py", line 153, in get
    yield from self.connect()
  File "D:\Users\Null\AppData\Local\Continuum\miniconda3\lib\site-packages\peewee_async.py", line 303, in connect
    yield from self.database.connect_async(loop=self.loop)
  File "D:\Users\Null\AppData\Local\Continuum\miniconda3\lib\site-packages\peewee_async.py", line 907, in connect_async
    yield from conn.connect()
  File "D:\Users\Null\AppData\Local\Continuum\miniconda3\lib\site-packages\peewee_async.py", line 1260, in connect
    **self.connect_kwargs)
  File "D:\Users\Null\AppData\Local\Continuum\miniconda3\lib\site-packages\aiomysql\pool.py", line 29, in _create_pool
    await pool._fill_free_pool(False)
  File "D:\Users\Null\AppData\Local\Continuum\miniconda3\lib\site-packages\aiomysql\pool.py", line 168, in _fill_free_pool
    **self._conn_kwargs)
  File "D:\Users\Null\AppData\Local\Continuum\miniconda3\lib\site-packages\aiomysql\connection.py", line 75, in _connect
    await conn._connect()
  File "D:\Users\Null\AppData\Local\Continuum\miniconda3\lib\site-packages\aiomysql\connection.py", line 523, in _connect
    self._host) from e
pymysql.err.OperationalError: (2003, "Can't connect to MySQL server on '127.0.0.1'")
[2019-12-20 17:06:19] [INFO] [MainThread] [handlers.py:44] Response Infomations:
+-----Headers-----+
| Content-Type    | text/plain      

Body:
| Traceback (most recent call last):
| 
[2019-12-20 17:06:19] [INFO] [MainThread] [handlers.py:63] Request Infomations:
+-----Headers-----+
| Host            | 127.0.0.1:8084  
| Connection      | keep-alive      
| Content-Length  | 48              
| Accept          | application/json, text/plain, */* 
| Origin          | http://localhost:8080 
| User-Agent      | Mozilla/5.0 (Windows NT 10.0; WOW64) AppleWebKit/537.36 (KHTML, like Gecko) Chrome/78.0.3904.87 Safari/537.36 
| Content-Type    | application/json;charset=UTF-8 
| Sec-Fetch-Site  | cross-site      
| Sec-Fetch-Mode  | cors            
| Referer         | http://localhost:8080/login 
| Accept-Encoding | gzip, deflate, br 
| Accept-Language | zh-CN,zh;q=0.9  
+----Arguments----+
| 'account'       | '123456@163.com' 
| 'password'      | '123456'        

[2019-12-20 17:06:19] [ERROR] [MainThread] [handlers.py:105] Uncaught exception POST /login/ (127.0.0.1)
HTTPServerRequest(protocol='http', host='127.0.0.1:8084', method='POST', uri='/login/', version='HTTP/1.1', remote_ip='127.0.0.1')
Traceback (most recent call last):
  File "D:\Users\Null\AppData\Local\Continuum\miniconda3\lib\site-packages\aiomysql\connection.py", line 503, in _connect
    await self._request_authentication()
  File "D:\Users\Null\AppData\Local\Continuum\miniconda3\lib\site-packages\aiomysql\connection.py", line 796, in _request_authentication
    await self._process_auth(plugin_name, auth_packet)
  File "D:\Users\Null\AppData\Local\Continuum\miniconda3\lib\site-packages\aiomysql\connection.py", line 848, in _process_auth
    pkt = await self._read_packet()
  File "D:\Users\Null\AppData\Local\Continuum\miniconda3\lib\site-packages\aiomysql\connection.py", line 593, in _read_packet
    packet.check_error()
  File "D:\Users\Null\AppData\Local\Continuum\miniconda3\lib\site-packages\pymysql\protocol.py", line 220, in check_error
    err.raise_mysql_exception(self._data)
  File "D:\Users\Null\AppData\Local\Continuum\miniconda3\lib\site-packages\pymysql\err.py", line 109, in raise_mysql_exception
    raise errorclass(errno, errval)
pymysql.err.OperationalError: (1045, "Access denied for user 'root'@'localhost' (using password: NO)")

The above exception was the direct cause of the following exception:

Traceback (most recent call last):
  File "D:\Users\Null\AppData\Local\Continuum\miniconda3\lib\site-packages\tornado\web.py", line 1699, in _execute
    result = await result
  File "F:\MagicTestPlatform\apps\users\handlers.py", line 87, in post
    user = await self.application.objects.get(User, account=account)
  File "D:\Users\Null\AppData\Local\Continuum\miniconda3\lib\site-packages\peewee_async.py", line 153, in get
    yield from self.connect()
  File "D:\Users\Null\AppData\Local\Continuum\miniconda3\lib\site-packages\peewee_async.py", line 303, in connect
    yield from self.database.connect_async(loop=self.loop)
  File "D:\Users\Null\AppData\Local\Continuum\miniconda3\lib\site-packages\peewee_async.py", line 907, in connect_async
    yield from conn.connect()
  File "D:\Users\Null\AppData\Local\Continuum\miniconda3\lib\site-packages\peewee_async.py", line 1260, in connect
    **self.connect_kwargs)
  File "D:\Users\Null\AppData\Local\Continuum\miniconda3\lib\site-packages\aiomysql\pool.py", line 29, in _create_pool
    await pool._fill_free_pool(False)
  File "D:\Users\Null\AppData\Local\Continuum\miniconda3\lib\site-packages\aiomysql\pool.py", line 168, in _fill_free_pool
    **self._conn_kwargs)
  File "D:\Users\Null\AppData\Local\Continuum\miniconda3\lib\site-packages\aiomysql\connection.py", line 75, in _connect
    await conn._connect()
  File "D:\Users\Null\AppData\Local\Continuum\miniconda3\lib\site-packages\aiomysql\connection.py", line 523, in _connect
    self._host) from e
pymysql.err.OperationalError: (2003, "Can't connect to MySQL server on '127.0.0.1'")
[2019-12-20 17:06:19] [INFO] [MainThread] [handlers.py:44] Response Infomations:
+-----Headers-----+
| Content-Type    | text/plain      

Body:
| Traceback (most recent call last):
| 
