[2019-12-23 11:47:39] [INFO] [MainThread] [handlers.py:63] Request Infomations:
+-----Headers-----+
| Authorization   | eyJ0eXAiOiJKV1QiLCJhbGciOiJIUzI1NiJ9.eyJpZCI6MSwibmlja19uYW1lIjpudWxsLCJleHAiOjE1NzY4MzI4MTV9.sQQNRJBoSPADTJuoFhLd7fMD0Jg2yjuDpjZ8v38nVQA 
| Content-Type    | application/json 
| User-Agent      | PostmanRuntime/7.21.0 
| Accept          | */*             
| Cache-Control   | no-cache        
| Postman-Token   | 17991cbb-cae9-4c3a-bc32-17510e2e5032 
| Host            | 127.0.0.1:8084  
| Accept-Encoding | gzip, deflate   
| Content-Length  | 80              
| Connection      | keep-alive      
+----Arguments----+
| 'name'          | '≤‚ ‘'            
| 'params_type'   | 1               
| 'params'        | '1312222222222222222222222' 

[2019-12-23 11:47:39] [ERROR] [MainThread] [handlers.py:105] Uncaught exception DELETE /public_params/1/ (127.0.0.1)
HTTPServerRequest(protocol='http', host='127.0.0.1:8084', method='DELETE', uri='/public_params/1/', version='HTTP/1.1', remote_ip='127.0.0.1')
Traceback (most recent call last):
  File "D:\Users\Null\AppData\Local\Continuum\miniconda3\lib\site-packages\aiomysql\connection.py", line 503, in _connect
    await self._request_authentication()
  File "D:\Users\Null\AppData\Local\Continuum\miniconda3\lib\site-packages\aiomysql\connection.py", line 796, in _request_authentication
    await self._process_auth(plugin_name, auth_packet)
  File "D:\Users\Null\AppData\Local\Continuum\miniconda3\lib\site-packages\aiomysql\connection.py", line 848, in _process_auth
    pkt = await self._read_packet()
  File "D:\Users\Null\AppData\Local\Continuum\miniconda3\lib\site-packages\aiomysql\connection.py", line 593, in _read_packet
    packet.check_error()
  File "D:\Users\Null\AppData\Local\Continuum\miniconda3\lib\site-packages\pymysql\protocol.py", line 220, in check_error
    err.raise_mysql_exception(self._data)
  File "D:\Users\Null\AppData\Local\Continuum\miniconda3\lib\site-packages\pymysql\err.py", line 109, in raise_mysql_exception
    raise errorclass(errno, errval)
pymysql.err.OperationalError: (1045, "Access denied for user 'root'@'localhost' (using password: NO)")

The above exception was the direct cause of the following exception:

Traceback (most recent call last):
  File "D:\Users\Null\AppData\Local\Continuum\miniconda3\lib\site-packages\tornado\web.py", line 1699, in _execute
    result = await result
  File "F:\MagicTestPlatform\common\core.py", line 67, in wrapper
    user = await self.application.objects.get(User, id=user_id)
  File "D:\Users\Null\AppData\Local\Continuum\miniconda3\lib\site-packages\peewee_async.py", line 153, in get
    yield from self.connect()
  File "D:\Users\Null\AppData\Local\Continuum\miniconda3\lib\site-packages\peewee_async.py", line 303, in connect
    yield from self.database.connect_async(loop=self.loop)
  File "D:\Users\Null\AppData\Local\Continuum\miniconda3\lib\site-packages\peewee_async.py", line 907, in connect_async
    yield from conn.connect()
  File "D:\Users\Null\AppData\Local\Continuum\miniconda3\lib\site-packages\peewee_async.py", line 1260, in connect
    **self.connect_kwargs)
  File "D:\Users\Null\AppData\Local\Continuum\miniconda3\lib\site-packages\aiomysql\pool.py", line 29, in _create_pool
    await pool._fill_free_pool(False)
  File "D:\Users\Null\AppData\Local\Continuum\miniconda3\lib\site-packages\aiomysql\pool.py", line 168, in _fill_free_pool
    **self._conn_kwargs)
  File "D:\Users\Null\AppData\Local\Continuum\miniconda3\lib\site-packages\aiomysql\connection.py", line 75, in _connect
    await conn._connect()
  File "D:\Users\Null\AppData\Local\Continuum\miniconda3\lib\site-packages\aiomysql\connection.py", line 523, in _connect
    self._host) from e
pymysql.err.OperationalError: (2003, "Can't connect to MySQL server on '127.0.0.1'")
[2019-12-23 11:47:40] [INFO] [MainThread] [handlers.py:44] Response Infomations:
+-----Headers-----+
| Content-Type    | text/plain      

Body:
| Traceback (most recent call last):
| 
