[2019-12-11 15:08:06] [INFO] [MainThread] [handlers.py:63] Request Infomations:
+-----Headers-----+
| Content-Type    | application/json 
| Authorization   | eyJ0eXAiOiJKV1QiLCJhbGciOiJIUzI1NiJ9.eyJpZCI6MSwibmlja19uYW1lIjpudWxsLCJleHAiOjE1NzU1Mjc0MTd9.x6DWIiifOqsbafgij7B001K5i7WHrzuvNmDyuVWuRNU 
| User-Agent      | PostmanRuntime/7.20.1 
| Accept          | */*             
| Cache-Control   | no-cache        
| Postman-Token   | e3bf1686-5ad9-47bc-86d9-ff31c2cddb2b 
| Host            | 127.0.0.1:8084  
| Accept-Encoding | gzip, deflate   
| Content-Length  | 141             
| Connection      | keep-alive      
+----Arguments----+
| 'test_name'     | '测试1'           
| 'interfaces'    | [8, 9]          
| 'assertion'     | '12313'         
| 'db'            | 2               
| 'check_db'      | '123'           
| 'desc'          | '21q313132'     

[2019-12-11 15:08:06] [INFO] [MainThread] [handlers.py:44] Response Infomations:
+-----Headers-----+
| Content-Type    | application/json 

Body:
| {
|     "code": 10020,
|     "msg": "这个用例已经创建！",
|     "data": null
| }
[2019-12-11 15:08:28] [INFO] [MainThread] [handlers.py:63] Request Infomations:
+-----Headers-----+
| Content-Type    | application/json 
| Authorization   | eyJ0eXAiOiJKV1QiLCJhbGciOiJIUzI1NiJ9.eyJpZCI6MSwibmlja19uYW1lIjpudWxsLCJleHAiOjE1NzU1Mjc0MTd9.x6DWIiifOqsbafgij7B001K5i7WHrzuvNmDyuVWuRNU 
| User-Agent      | PostmanRuntime/7.20.1 
| Accept          | */*             
| Cache-Control   | no-cache        
| Postman-Token   | e905f7b2-cb05-4e40-a67b-145a31fcf594 
| Host            | 127.0.0.1:8084  
| Accept-Encoding | gzip, deflate   
| Content-Length  | 141             
| Connection      | keep-alive      
+----Arguments----+
| 'test_name'     | '测试2'           
| 'interfaces'    | [8, 9]          
| 'assertion'     | '12313'         
| 'db'            | 2               
| 'check_db'      | '123'           
| 'desc'          | '21q313132'     

[2019-12-11 15:08:28] [ERROR] [MainThread] [handlers.py:105] Uncaught exception POST /cases/ (127.0.0.1)
HTTPServerRequest(protocol='http', host='127.0.0.1:8084', method='POST', uri='/cases/', version='HTTP/1.1', remote_ip='127.0.0.1')
Traceback (most recent call last):
  File "D:\Users\Null\AppData\Local\Continuum\miniconda3\lib\site-packages\peewee_async.py", line 170, in get
    return list(result)[0]
IndexError: list index out of range

During handling of the above exception, another exception occurred:

Traceback (most recent call last):
  File "F:\MagicTestPlatform\apps\interface_test\handlers.py", line 232, in post
    TestCases, test_name=form.test_name.data
  File "D:\Users\Null\AppData\Local\Continuum\miniconda3\lib\site-packages\peewee_async.py", line 172, in get
    raise model.DoesNotExist
apps.interface_test.models.TestCasesDoesNotExist

During handling of the above exception, another exception occurred:

Traceback (most recent call last):
  File "D:\Users\Null\AppData\Local\Continuum\miniconda3\lib\site-packages\tornado\web.py", line 1699, in _execute
    result = await result
  File "F:\MagicTestPlatform\apps\utils\wrappers.py", line 25, in wrapper
    await method(self, *args, **kwargs)
  File "F:\MagicTestPlatform\apps\interface_test\handlers.py", line 247, in post
    desc=form.desc.data
  File "D:\Users\Null\AppData\Local\Continuum\miniconda3\lib\site-packages\peewee_async.py", line 178, in create
    inst = model_(**data)
  File "D:\Users\Null\AppData\Local\Continuum\miniconda3\lib\site-packages\peewee.py", line 4933, in __init__
    setattr(self, k, v)
  File "D:\Users\Null\AppData\Local\Continuum\miniconda3\lib\site-packages\playhouse\fields.py", line 177, in __set__
    query.add(value, clear_existing=True)
  File "D:\Users\Null\AppData\Local\Continuum\miniconda3\lib\site-packages\playhouse\fields.py", line 201, in add
    self.clear()
  File "D:\Users\Null\AppData\Local\Continuum\miniconda3\lib\site-packages\playhouse\fields.py", line 247, in clear
    .where(self._field_descriptor.src_fk == self._instance)
  File "D:\Users\Null\AppData\Local\Continuum\miniconda3\lib\site-packages\peewee.py", line 3614, in execute
    return self.database.rows_affected(self._execute())
  File "D:\Users\Null\AppData\Local\Continuum\miniconda3\lib\site-packages\peewee.py", line 2939, in _execute
    return self.database.execute_sql(sql, params, self.require_commit)
  File "D:\Users\Null\AppData\Local\Continuum\miniconda3\lib\site-packages\peewee_async.py", line 1035, in execute_sql
    "Error, sync query is not allowed! Call the `.set_allow_sync()` "
AssertionError: Error, sync query is not allowed! Call the `.set_allow_sync()` or use the `.allow_sync()` context manager.
[2019-12-11 15:08:28] [INFO] [MainThread] [handlers.py:44] Response Infomations:
+-----Headers-----+
| Content-Type    | text/plain      

Body:
| Traceback (most recent call last):
| 
