[2019-11-29 17:44:10] [INFO] [MainThread] [handlers.py:63] Request Infomations:
+-----Headers-----+
| Connection      | close           
| Host            | 127.0.0.1:62518 
| Content-Length  | 51              
| Content-Type    | application/x-www-form-urlencoded 
| Accept-Encoding | gzip            
+----Arguments----+
| 'account'       | '123456@163.com' 
| 'password'      | '123456'        

[2019-11-29 17:44:10] [INFO] [MainThread] [handlers.py:44] Response Infomations:
+-----Headers-----+
| Content-Type    | application/json 

Body:
| {
|     "code": 1,
|     "msg": "登陆成功",
|     "data": {
|         "id": 1,
|         "nick_name": "123456@163.com",
|         "token": "eyJ0eXAiOiJKV1QiLCJhbGciOiJIUzI1NiJ9.eyJpZCI6MSwibmlja19uYW1lIjpudWxsLCJleHAiOjE1NzUwMjA2NTB9.OOXW9cqfIsS-qqkLBvvgMG1XR3Cp3vFEVV_cfKepuzw"
|     }
| }
[2019-11-29 17:44:10] [INFO] [MainThread] [handlers.py:63] Request Infomations:
+-----Headers-----+
| Connection      | close           
| Host            | 127.0.0.1:62523 
| Content-Length  | 29              
| Content-Type    | application/x-www-form-urlencoded 
| Accept-Encoding | gzip            
+----Arguments----+
| 'account'       | '140056@163.com' 

[2019-11-29 17:44:10] [INFO] [MainThread] [handlers.py:44] Response Infomations:
+-----Headers-----+
| Content-Type    | application/json 

Body:
| {
|     "code": 1,
|     "msg": "验证码已发送，请注意接收",
|     "data": {
|         "account": "140056@163.com",
|         "VerCode": "0566"
|     }
| }
[2019-11-29 17:44:10] [INFO] [MainThread] [handlers.py:63] Request Infomations:
+-----Headers-----+
| Connection      | close           
| Host            | 127.0.0.1:62523 
| Content-Length  | 67              
| Content-Type    | application/x-www-form-urlencoded 
| Accept-Encoding | gzip            
+----Arguments----+
| 'account'       | '140056@163.com' 
| 'code'          | '0566'          
| 'password'      | '123456'        

[2019-11-29 17:44:10] [ERROR] [MainThread] [handlers.py:105] Uncaught exception POST /register/ (127.0.0.1)
HTTPServerRequest(protocol='http', host='127.0.0.1:62523', method='POST', uri='/register/', version='HTTP/1.1', remote_ip='127.0.0.1')
Traceback (most recent call last):
  File "D:\Users\Null\AppData\Local\Continuum\miniconda3\lib\site-packages\peewee_async.py", line 1540, in _run_sql
    yield from cursor.execute(operation, *args, **kwargs)
  File "D:\Users\Null\AppData\Local\Continuum\miniconda3\lib\site-packages\aiomysql\cursors.py", line 239, in execute
    await self._query(query)
  File "D:\Users\Null\AppData\Local\Continuum\miniconda3\lib\site-packages\aiomysql\cursors.py", line 457, in _query
    await conn.query(q)
  File "D:\Users\Null\AppData\Local\Continuum\miniconda3\lib\site-packages\aiomysql\connection.py", line 428, in query
    await self._read_query_result(unbuffered=unbuffered)
  File "D:\Users\Null\AppData\Local\Continuum\miniconda3\lib\site-packages\aiomysql\connection.py", line 622, in _read_query_result
    await result.read()
  File "D:\Users\Null\AppData\Local\Continuum\miniconda3\lib\site-packages\aiomysql\connection.py", line 1105, in read
    first_packet = await self.connection._read_packet()
  File "D:\Users\Null\AppData\Local\Continuum\miniconda3\lib\site-packages\aiomysql\connection.py", line 561, in _read_packet
    packet_header = await self._read_bytes(4)
  File "D:\Users\Null\AppData\Local\Continuum\miniconda3\lib\site-packages\aiomysql\connection.py", line 598, in _read_bytes
    data = await self._reader.readexactly(num_bytes)
  File "D:\Users\Null\AppData\Local\Continuum\miniconda3\lib\asyncio\streams.py", line 679, in readexactly
    await self._wait_for_data('readexactly')
  File "D:\Users\Null\AppData\Local\Continuum\miniconda3\lib\asyncio\streams.py", line 473, in _wait_for_data
    await self._waiter
RuntimeError: Task <Task pending coro=<RequestHandler._execute() running at D:\Users\Null\AppData\Local\Continuum\miniconda3\lib\site-packages\tornado\web.py:1699> cb=[_HandlerDelegate.execute.<locals>.<lambda>() at D:\Users\Null\AppData\Local\Continuum\miniconda3\lib\site-packages\tornado\web.py:2329]> got Future <Future pending> attached to a different loop

During handling of the above exception, another exception occurred:

Traceback (most recent call last):
  File "D:\Users\Null\AppData\Local\Continuum\miniconda3\lib\site-packages\tornado\web.py", line 1699, in _execute
    result = await result
  File "F:\MagicTestPlatform\apps\users\handlers.py", line 73, in post
    await self.application.objects.get(User, account=account)
  File "D:\Users\Null\AppData\Local\Continuum\miniconda3\lib\site-packages\peewee_async.py", line 169, in get
    result = yield from self.execute(query)
  File "D:\Users\Null\AppData\Local\Continuum\miniconda3\lib\site-packages\peewee_async.py", line 269, in execute
    return (yield from execute(query))
  File "D:\Users\Null\AppData\Local\Continuum\miniconda3\lib\site-packages\peewee_async.py", line 433, in execute
    return (yield from coroutine(query))
  File "D:\Users\Null\AppData\Local\Continuum\miniconda3\lib\site-packages\peewee_async.py", line 574, in select
    cursor = yield from _execute_query_async(query)
  File "D:\Users\Null\AppData\Local\Continuum\miniconda3\lib\site-packages\peewee_async.py", line 1558, in _execute_query_async
    return (yield from _run_sql(query.database, *query.sql()))
  File "D:\Users\Null\AppData\Local\Continuum\miniconda3\lib\site-packages\peewee_async.py", line 1542, in _run_sql
    yield from cursor.release
  File "D:\Users\Null\AppData\Local\Continuum\miniconda3\lib\site-packages\peewee_async.py", line 1290, in release_cursor
    self.release(conn)
  File "D:\Users\Null\AppData\Local\Continuum\miniconda3\lib\site-packages\peewee_async.py", line 1250, in release
    self.pool.release(conn)
  File "D:\Users\Null\AppData\Local\Continuum\miniconda3\lib\site-packages\aiomysql\pool.py", line 215, in release
    fut = self._loop.create_task(self._wakeup())
  File "D:\Users\Null\AppData\Local\Continuum\miniconda3\lib\asyncio\base_events.py", line 398, in create_task
    self._check_closed()
  File "D:\Users\Null\AppData\Local\Continuum\miniconda3\lib\asyncio\base_events.py", line 475, in _check_closed
    raise RuntimeError('Event loop is closed')
RuntimeError: Event loop is closed
[2019-11-29 17:44:10] [INFO] [MainThread] [handlers.py:44] Response Infomations:
+-----Headers-----+
| Content-Type    | text/plain      

Body:
| Traceback (most recent call last):
| 
[2019-11-29 17:44:11] [INFO] [MainThread] [handlers.py:63] Request Infomations:
+-----Headers-----+
| Connection      | close           
| Host            | 127.0.0.1:62530 
| Content-Length  | 29              
| Content-Type    | application/x-www-form-urlencoded 
| Accept-Encoding | gzip            
+----Arguments----+
| 'account'       | '148001@163.com' 

[2019-11-29 17:44:11] [INFO] [MainThread] [handlers.py:44] Response Infomations:
+-----Headers-----+
| Content-Type    | application/json 

Body:
| {
|     "code": 1,
|     "msg": "验证码已发送，请注意接收",
|     "data": {
|         "account": "148001@163.com",
|         "VerCode": "2087"
|     }
| }
