[2019-12-11 15:06:17] [INFO] [MainThread] [handlers.py:63] Request Infomations:
+-----Headers-----+
| Content-Type    | application/json 
| Authorization   | eyJ0eXAiOiJKV1QiLCJhbGciOiJIUzI1NiJ9.eyJpZCI6MSwibmlja19uYW1lIjpudWxsLCJleHAiOjE1NzU1Mjc0MTd9.x6DWIiifOqsbafgij7B001K5i7WHrzuvNmDyuVWuRNU 
| User-Agent      | PostmanRuntime/7.20.1 
| Accept          | */*             
| Cache-Control   | no-cache        
| Postman-Token   | 6212d0ec-07c2-451b-807d-6849fdfbbdb8 
| Host            | 127.0.0.1:8084  
| Accept-Encoding | gzip, deflate   
| Content-Length  | 141             
| Connection      | keep-alive      
+----Arguments----+
| 'test_name'     | '≤‚ ‘1'           
| 'interfaces'    | [8, 9]          
| 'assertion'     | '12313'         
| 'db'            | 2               
| 'check_db'      | '123'           
| 'desc'          | '21q313132'     

[2019-12-11 15:06:17] [ERROR] [MainThread] [handlers.py:105] Uncaught exception POST /cases/ (127.0.0.1)
HTTPServerRequest(protocol='http', host='127.0.0.1:8084', method='POST', uri='/cases/', version='HTTP/1.1', remote_ip='127.0.0.1')
Traceback (most recent call last):
  File "D:\Users\Null\AppData\Local\Continuum\miniconda3\lib\site-packages\peewee_async.py", line 170, in get
    return list(result)[0]
IndexError: list index out of range

During handling of the above exception, another exception occurred:

Traceback (most recent call last):
  File "F:\MagicTestPlatform\apps\interface_test\handlers.py", line 232, in post
    TestCases, test_name=form.test_name.data
  File "D:\Users\Null\AppData\Local\Continuum\miniconda3\lib\site-packages\peewee_async.py", line 172, in get
    raise model.DoesNotExist
apps.interface_test.models.TestCasesDoesNotExist

During handling of the above exception, another exception occurred:

Traceback (most recent call last):
  File "D:\Users\Null\AppData\Local\Continuum\miniconda3\lib\site-packages\tornado\web.py", line 1699, in _execute
    result = await result
  File "F:\MagicTestPlatform\apps\utils\wrappers.py", line 25, in wrapper
    await method(self, *args, **kwargs)
  File "F:\MagicTestPlatform\apps\interface_test\handlers.py", line 240, in post
    test_name=form.interface_name.data,
AttributeError: 'TestCaseForm' object has no attribute 'interface_name'
[2019-12-11 15:06:17] [INFO] [MainThread] [handlers.py:44] Response Infomations:
+-----Headers-----+
| Content-Type    | text/plain      

Body:
| Traceback (most recent call last):
| 
