[2019-12-23 18:21:18] [INFO] [MainThread] [handlers.py:63] Request Infomations:
+-----Headers-----+
| Content-Type    | application/json 
| Authorization   | eyJ0eXAiOiJKV1QiLCJhbGciOiJIUzI1NiJ9.eyJpZCI6MSwibmlja19uYW1lIjpudWxsLCJleHAiOjE1NzY4MzI4MTV9.sQQNRJBoSPADTJuoFhLd7fMD0Jg2yjuDpjZ8v38nVQA 
| User-Agent      | PostmanRuntime/7.21.0 
| Accept          | */*             
| Cache-Control   | no-cache        
| Postman-Token   | be9c9525-f5bb-4a67-b42f-3a07980ec8b4 
| Host            | 127.0.0.1:8084  
| Accept-Encoding | gzip, deflate   
| Content-Length  | 62              
| Connection      | keep-alive      
+----Arguments----+
| 'suite_name'    | '123213'        
| 'cases'         | [33]            
| 'desc'          | '123123'        

[2019-12-23 18:21:18] [ERROR] [MainThread] [handlers.py:105] Uncaught exception POST /suites/ (127.0.0.1)
HTTPServerRequest(protocol='http', host='127.0.0.1:8084', method='POST', uri='/suites/', version='HTTP/1.1', remote_ip='127.0.0.1')
Traceback (most recent call last):
  File "D:\Users\Null\AppData\Local\Continuum\miniconda3\lib\site-packages\peewee_async.py", line 170, in get
    return list(result)[0]
IndexError: list index out of range

During handling of the above exception, another exception occurred:

Traceback (most recent call last):
  File "F:\MagicTestPlatform\apps\interface_test\handlers.py", line 596, in post
    TestSuite, suite_name=form.suite_name.data
  File "D:\Users\Null\AppData\Local\Continuum\miniconda3\lib\site-packages\peewee_async.py", line 172, in get
    raise model.DoesNotExist
apps.interface_test.models.TestSuiteDoesNotExist

During handling of the above exception, another exception occurred:

Traceback (most recent call last):
  File "D:\Users\Null\AppData\Local\Continuum\miniconda3\lib\site-packages\tornado\web.py", line 1699, in _execute
    result = await result
  File "F:\MagicTestPlatform\common\core.py", line 69, in wrapper
    await method(self, *args, **kwargs)
  File "F:\MagicTestPlatform\apps\interface_test\handlers.py", line 610, in post
    if form.cases.data > 0:
TypeError: '>' not supported between instances of 'list' and 'int'
[2019-12-23 18:21:18] [INFO] [MainThread] [handlers.py:44] Response Infomations:
+-----Headers-----+
| Content-Type    | text/plain      

Body:
| Traceback (most recent call last):
| 
