[2019-12-24 10:57:50] [INFO] [MainThread] [handlers.py:63] Request Infomations:
+-----Headers-----+
| Content-Type    | application/json 
| Authorization   | eyJ0eXAiOiJKV1QiLCJhbGciOiJIUzI1NiJ9.eyJpZCI6MSwibmlja19uYW1lIjpudWxsLCJleHAiOjE1NzY4MzI4MTV9.sQQNRJBoSPADTJuoFhLd7fMD0Jg2yjuDpjZ8v38nVQA 
| User-Agent      | PostmanRuntime/7.21.0 
| Accept          | */*             
| Cache-Control   | no-cache        
| Postman-Token   | abdb62ee-59e8-4de5-8287-e53b45d993d1 
| Host            | 127.0.0.1:8084  
| Accept-Encoding | gzip, deflate   
| Content-Length  | 65              
| Connection      | keep-alive      
+----Arguments----+
| 'suite_name'    | '123222213'     
| 'cases'         | [33]            
| 'desc'          | '123123'        

[2019-12-24 10:57:50] [ERROR] [MainThread] [handlers.py:105] Uncaught exception GET /suites/ (127.0.0.1)
HTTPServerRequest(protocol='http', host='127.0.0.1:8084', method='GET', uri='/suites/', version='HTTP/1.1', remote_ip='127.0.0.1')
Traceback (most recent call last):
  File "D:\Users\Null\AppData\Local\Continuum\miniconda3\lib\site-packages\tornado\web.py", line 1699, in _execute
    result = await result
  File "F:\MagicTestPlatform\common\core.py", line 69, in wrapper
    await method(self, *args, **kwargs)
  File "F:\MagicTestPlatform\apps\interface_test\handlers.py", line 609, in get
    'case': [model_to_dict(suite_case)for suite_case in suite_case_query]
  File "F:\MagicTestPlatform\apps\interface_test\handlers.py", line 609, in <listcomp>
    'case': [model_to_dict(suite_case)for suite_case in suite_case_query]
  File "D:\Users\Null\AppData\Local\Continuum\miniconda3\lib\site-packages\playhouse\shortcuts.py", line 115, in model_to_dict
    rel_obj = getattr(model, field.name)
  File "D:\Users\Null\AppData\Local\Continuum\miniconda3\lib\site-packages\peewee.py", line 1386, in __get__
    return self.get_object_or_id(instance)
  File "D:\Users\Null\AppData\Local\Continuum\miniconda3\lib\site-packages\peewee.py", line 1377, in get_object_or_id
    obj = self.rel_model.get(self.field.to_field == rel_id)
  File "D:\Users\Null\AppData\Local\Continuum\miniconda3\lib\site-packages\peewee.py", line 4988, in get
    return sq.get()
  File "D:\Users\Null\AppData\Local\Continuum\miniconda3\lib\site-packages\peewee.py", line 3220, in get
    return next(clone.execute())
  File "D:\Users\Null\AppData\Local\Continuum\miniconda3\lib\site-packages\peewee.py", line 3274, in execute
    self._qr = ResultWrapper(model_class, self._execute(), query_meta)
  File "D:\Users\Null\AppData\Local\Continuum\miniconda3\lib\site-packages\peewee.py", line 2939, in _execute
    return self.database.execute_sql(sql, params, self.require_commit)
  File "D:\Users\Null\AppData\Local\Continuum\miniconda3\lib\site-packages\peewee_async.py", line 1035, in execute_sql
    "Error, sync query is not allowed! Call the `.set_allow_sync()` "
AssertionError: Error, sync query is not allowed! Call the `.set_allow_sync()` or use the `.allow_sync()` context manager.
[2019-12-24 10:57:50] [INFO] [MainThread] [handlers.py:44] Response Infomations:
+-----Headers-----+
| Content-Type    | text/plain      

Body:
| Traceback (most recent call last):
| 
[2019-12-24 10:59:46] [INFO] [MainThread] [handlers.py:63] Request Infomations:
+-----Headers-----+
| Content-Type    | application/json 
| Authorization   | eyJ0eXAiOiJKV1QiLCJhbGciOiJIUzI1NiJ9.eyJpZCI6MSwibmlja19uYW1lIjpudWxsLCJleHAiOjE1NzY4MzI4MTV9.sQQNRJBoSPADTJuoFhLd7fMD0Jg2yjuDpjZ8v38nVQA 
| User-Agent      | PostmanRuntime/7.21.0 
| Accept          | */*             
| Cache-Control   | no-cache        
| Postman-Token   | b9458e32-c8c3-41f6-addf-29cbaf8925d2 
| Host            | 127.0.0.1:8084  
| Accept-Encoding | gzip, deflate   
| Content-Length  | 65              
| Connection      | keep-alive      
+----Arguments----+
| 'suite_name'    | '123222213'     
| 'cases'         | [33]            
| 'desc'          | '123123'        

[2019-12-24 10:59:46] [INFO] [MainThread] [handlers.py:44] Response Infomations:
+-----Headers-----+
| Content-Type    | application/json 

Body:
| {
|     "code": 1,
|     "msg": "success",
|     "data": {
|         "suiteId": 3
|     }
| }
[2019-12-24 10:59:53] [INFO] [MainThread] [handlers.py:63] Request Infomations:
+-----Headers-----+
| Content-Type    | application/json 
| Authorization   | eyJ0eXAiOiJKV1QiLCJhbGciOiJIUzI1NiJ9.eyJpZCI6MSwibmlja19uYW1lIjpudWxsLCJleHAiOjE1NzY4MzI4MTV9.sQQNRJBoSPADTJuoFhLd7fMD0Jg2yjuDpjZ8v38nVQA 
| User-Agent      | PostmanRuntime/7.21.0 
| Accept          | */*             
| Cache-Control   | no-cache        
| Postman-Token   | 5ac8e5c8-6548-4402-8ead-5dc8b9be452c 
| Host            | 127.0.0.1:8084  
| Accept-Encoding | gzip, deflate   
| Content-Length  | 65              
| Connection      | keep-alive      
+----Arguments----+
| 'suite_name'    | '123222213'     
| 'cases'         | [33]            
| 'desc'          | '123123'        

[2019-12-24 10:59:53] [ERROR] [MainThread] [handlers.py:105] Uncaught exception GET /suites/ (127.0.0.1)
HTTPServerRequest(protocol='http', host='127.0.0.1:8084', method='GET', uri='/suites/', version='HTTP/1.1', remote_ip='127.0.0.1')
Traceback (most recent call last):
  File "D:\Users\Null\AppData\Local\Continuum\miniconda3\lib\site-packages\tornado\web.py", line 1699, in _execute
    result = await result
  File "F:\MagicTestPlatform\common\core.py", line 69, in wrapper
    await method(self, *args, **kwargs)
  File "F:\MagicTestPlatform\apps\interface_test\handlers.py", line 609, in get
    'case': [model_to_dict(suite_case)for suite_case in suite_case_query]
  File "F:\MagicTestPlatform\apps\interface_test\handlers.py", line 609, in <listcomp>
    'case': [model_to_dict(suite_case)for suite_case in suite_case_query]
  File "D:\Users\Null\AppData\Local\Continuum\miniconda3\lib\site-packages\playhouse\shortcuts.py", line 115, in model_to_dict
    rel_obj = getattr(model, field.name)
  File "D:\Users\Null\AppData\Local\Continuum\miniconda3\lib\site-packages\peewee.py", line 1386, in __get__
    return self.get_object_or_id(instance)
  File "D:\Users\Null\AppData\Local\Continuum\miniconda3\lib\site-packages\peewee.py", line 1377, in get_object_or_id
    obj = self.rel_model.get(self.field.to_field == rel_id)
  File "D:\Users\Null\AppData\Local\Continuum\miniconda3\lib\site-packages\peewee.py", line 4988, in get
    return sq.get()
  File "D:\Users\Null\AppData\Local\Continuum\miniconda3\lib\site-packages\peewee.py", line 3220, in get
    return next(clone.execute())
  File "D:\Users\Null\AppData\Local\Continuum\miniconda3\lib\site-packages\peewee.py", line 3274, in execute
    self._qr = ResultWrapper(model_class, self._execute(), query_meta)
  File "D:\Users\Null\AppData\Local\Continuum\miniconda3\lib\site-packages\peewee.py", line 2939, in _execute
    return self.database.execute_sql(sql, params, self.require_commit)
  File "D:\Users\Null\AppData\Local\Continuum\miniconda3\lib\site-packages\peewee_async.py", line 1035, in execute_sql
    "Error, sync query is not allowed! Call the `.set_allow_sync()` "
AssertionError: Error, sync query is not allowed! Call the `.set_allow_sync()` or use the `.allow_sync()` context manager.
[2019-12-24 10:59:53] [INFO] [MainThread] [handlers.py:44] Response Infomations:
+-----Headers-----+
| Content-Type    | text/plain      

Body:
| Traceback (most recent call last):
| 
