[2019-12-24 11:41:20] [INFO] [MainThread] [handlers.py:63] Request Infomations:
+-----Headers-----+
| Content-Type    | application/json 
| Authorization   | eyJ0eXAiOiJKV1QiLCJhbGciOiJIUzI1NiJ9.eyJpZCI6MSwibmlja19uYW1lIjpudWxsLCJleHAiOjE1NzY4MzI4MTV9.sQQNRJBoSPADTJuoFhLd7fMD0Jg2yjuDpjZ8v38nVQA 
| User-Agent      | PostmanRuntime/7.21.0 
| Accept          | */*             
| Cache-Control   | no-cache        
| Postman-Token   | 232bebc4-74d7-4b54-aef3-5bda8722b035 
| Host            | 127.0.0.1:8084  
| Accept-Encoding | gzip, deflate   
| Content-Length  | 70              
| Connection      | keep-alive      
+----Arguments----+
| 'suite_name'    | '12322222213'   
| 'cases'         | [34]            
| 'desc'          | '‘∫œ÷‘⁄'           

[2019-12-24 11:41:20] [ERROR] [MainThread] [handlers.py:105] Uncaught exception DELETE /suites/3/ (127.0.0.1)
HTTPServerRequest(protocol='http', host='127.0.0.1:8084', method='DELETE', uri='/suites/3/', version='HTTP/1.1', remote_ip='127.0.0.1')
Traceback (most recent call last):
  File "D:\Users\Null\AppData\Local\Continuum\miniconda3\lib\site-packages\peewee_async.py", line 1540, in _run_sql
    yield from cursor.execute(operation, *args, **kwargs)
  File "D:\Users\Null\AppData\Local\Continuum\miniconda3\lib\site-packages\aiomysql\cursors.py", line 239, in execute
    await self._query(query)
  File "D:\Users\Null\AppData\Local\Continuum\miniconda3\lib\site-packages\aiomysql\cursors.py", line 457, in _query
    await conn.query(q)
  File "D:\Users\Null\AppData\Local\Continuum\miniconda3\lib\site-packages\aiomysql\connection.py", line 428, in query
    await self._read_query_result(unbuffered=unbuffered)
  File "D:\Users\Null\AppData\Local\Continuum\miniconda3\lib\site-packages\aiomysql\connection.py", line 622, in _read_query_result
    await result.read()
  File "D:\Users\Null\AppData\Local\Continuum\miniconda3\lib\site-packages\aiomysql\connection.py", line 1105, in read
    first_packet = await self.connection._read_packet()
  File "D:\Users\Null\AppData\Local\Continuum\miniconda3\lib\site-packages\aiomysql\connection.py", line 593, in _read_packet
    packet.check_error()
  File "D:\Users\Null\AppData\Local\Continuum\miniconda3\lib\site-packages\pymysql\protocol.py", line 220, in check_error
    err.raise_mysql_exception(self._data)
  File "D:\Users\Null\AppData\Local\Continuum\miniconda3\lib\site-packages\pymysql\err.py", line 109, in raise_mysql_exception
    raise errorclass(errno, errval)
pymysql.err.IntegrityError: (1451, 'Cannot delete or update a parent row: a foreign key constraint fails (`magic`.`testcasesuite`, CONSTRAINT `testcasesuite_ibfk_1` FOREIGN KEY (`suite_id`) REFERENCES `testsuite` (`id`))')

During handling of the above exception, another exception occurred:

Traceback (most recent call last):
  File "D:\Users\Null\AppData\Local\Continuum\miniconda3\lib\site-packages\tornado\web.py", line 1699, in _execute
    result = await result
  File "F:\MagicTestPlatform\common\core.py", line 69, in wrapper
    await method(self, *args, **kwargs)
  File "F:\MagicTestPlatform\apps\interface_test\handlers.py", line 690, in delete
    await self.application.objects.delete(suite)
  File "D:\Users\Null\AppData\Local\Continuum\miniconda3\lib\site-packages\peewee_async.py", line 247, in delete
    return (yield from self.execute(query))
  File "D:\Users\Null\AppData\Local\Continuum\miniconda3\lib\site-packages\peewee_async.py", line 269, in execute
    return (yield from execute(query))
  File "D:\Users\Null\AppData\Local\Continuum\miniconda3\lib\site-packages\peewee_async.py", line 433, in execute
    return (yield from coroutine(query))
  File "D:\Users\Null\AppData\Local\Continuum\miniconda3\lib\site-packages\peewee_async.py", line 637, in delete
    cursor = yield from _execute_query_async(query)
  File "D:\Users\Null\AppData\Local\Continuum\miniconda3\lib\site-packages\peewee_async.py", line 1558, in _execute_query_async
    return (yield from _run_sql(query.database, *query.sql()))
  File "D:\Users\Null\AppData\Local\Continuum\miniconda3\lib\site-packages\peewee_async.py", line 1545, in _run_sql
    return cursor
  File "D:\Users\Null\AppData\Local\Continuum\miniconda3\lib\site-packages\peewee.py", line 3656, in __exit__
    reraise(new_type, new_type(*exc_args), traceback)
  File "D:\Users\Null\AppData\Local\Continuum\miniconda3\lib\site-packages\peewee.py", line 135, in reraise
    raise value.with_traceback(tb)
  File "D:\Users\Null\AppData\Local\Continuum\miniconda3\lib\site-packages\peewee_async.py", line 1540, in _run_sql
    yield from cursor.execute(operation, *args, **kwargs)
  File "D:\Users\Null\AppData\Local\Continuum\miniconda3\lib\site-packages\aiomysql\cursors.py", line 239, in execute
    await self._query(query)
  File "D:\Users\Null\AppData\Local\Continuum\miniconda3\lib\site-packages\aiomysql\cursors.py", line 457, in _query
    await conn.query(q)
  File "D:\Users\Null\AppData\Local\Continuum\miniconda3\lib\site-packages\aiomysql\connection.py", line 428, in query
    await self._read_query_result(unbuffered=unbuffered)
  File "D:\Users\Null\AppData\Local\Continuum\miniconda3\lib\site-packages\aiomysql\connection.py", line 622, in _read_query_result
    await result.read()
  File "D:\Users\Null\AppData\Local\Continuum\miniconda3\lib\site-packages\aiomysql\connection.py", line 1105, in read
    first_packet = await self.connection._read_packet()
  File "D:\Users\Null\AppData\Local\Continuum\miniconda3\lib\site-packages\aiomysql\connection.py", line 593, in _read_packet
    packet.check_error()
  File "D:\Users\Null\AppData\Local\Continuum\miniconda3\lib\site-packages\pymysql\protocol.py", line 220, in check_error
    err.raise_mysql_exception(self._data)
  File "D:\Users\Null\AppData\Local\Continuum\miniconda3\lib\site-packages\pymysql\err.py", line 109, in raise_mysql_exception
    raise errorclass(errno, errval)
peewee.IntegrityError: (1451, 'Cannot delete or update a parent row: a foreign key constraint fails (`magic`.`testcasesuite`, CONSTRAINT `testcasesuite_ibfk_1` FOREIGN KEY (`suite_id`) REFERENCES `testsuite` (`id`))')
[2019-12-24 11:41:20] [INFO] [MainThread] [handlers.py:44] Response Infomations:
+-----Headers-----+
| Content-Type    | text/plain      

Body:
| Traceback (most recent call last):
| 
